<mujoco model="SAHR_v76">

    <compiler angle="radian" meshdir="../meshes/" />
    <size njmax="500" nconmax="1000" />
    <asset>
        <mesh name="trunk_1" file="trunk_1.STL" />
        <mesh name="u_neck_1" file="u_neck_1.STL" />
        <mesh name="head_1" file="head_1.STL" />
        <mesh name="Head_Up" file="Head_Up.STL" />
        <mesh name="u_neck_bone_right" file="u_neck_bone_right.STL" />
        <mesh name="u_neck_bone_left" file="u_neck_bone_left.STL" />
        <mesh name="u_block_2" file="u_block_2.STL" />
        <mesh name="u_block_2_bone1" file="u_block_2_bone1.STL" />
        <mesh name="u_block_2_bone2" file="u_block_2_bone2.STL" />
        <mesh name="mx106_block_2" file="mx106_block_2.STL" />
        <mesh name="left_knee_1" file="left_knee_1.STL" />
        <mesh name="tibia_2" file="tibia_2.STL" />
        <mesh name="mx106_block_mir_2" file="mx106_block_mir_2.STL" />
        <mesh name="left_foot_1" file="left_foot_1.STL" />
        <mesh name="left_foot_1_0_foot_protection" file="left_foot_1_0_foot_protection.STL" />
        <mesh name="left_foot_cleat_front_right" file="left_foot_cleat_front_right.STL" />
        <mesh name="left_foot_cleat_front_left" file="left_foot_cleat_front_left.STL" />
        <mesh name="left_foot_cleat_back_right" file="left_foot_cleat_back_right.STL" />
        <mesh name="left_foot_cleat_back_left" file="left_foot_cleat_back_left.STL" />
        <mesh name="left_foot_bone_back" file="left_foot_bone_back.STL" />
        <mesh name="left_foot_bone_front" file="left_foot_bone_front.STL" />
        <mesh name="joint_block03" file="joint_block03.STL" />
        <mesh name="dubel03" file="dubel03.STL" />
        <mesh name="tibia_21" file="tibia_21.STL" />
        <mesh name="left_shin_panel" file="left_shin_panel.STL" />
        <mesh name="tibia_22" file="tibia_22.STL" />
        <mesh name="left_knee_bone_1" file="left_knee_bone_1.STL" />
        <mesh name="left_hip_panel" file="left_hip_panel.STL" />
        <mesh name="left_knee_bone_2" file="left_knee_bone_2.STL" />
        <mesh name="joint_block01" file="joint_block01.STL" />
        <mesh name="dubel01" file="dubel01.STL" />
        <mesh name="u_block_1" file="u_block_1.STL" />
        <mesh name="u_block_1_bone1" file="u_block_1_bone1.STL" />
        <mesh name="u_block_1_bone2" file="u_block_1_bone2.STL" />
        <mesh name="mx106_block_mir_1" file="mx106_block_mir_1.STL" />
        <mesh name="right_knee_1" file="right_knee_1.STL" />
        <mesh name="tibia_1" file="tibia_1.STL" />
        <mesh name="mx106_block_1" file="mx106_block_1.STL" />
        <mesh name="right_foot_1" file="right_foot_1.STL" />
        <mesh name="right_foot_cleat_front_left" file="right_foot_clear_front_left.STL" />
        <mesh name="right_foot_cleat_back_left" file="right_foot_cleat_back_left.STL" />
        <mesh name="right_foot_cleat_back_right" file="right_foot_cleat_back_right.STL" />
        <mesh name="right_foot_cleat_front_right" file="right_foot_cleat_front_right.STL" />
        <mesh name="right_foot_1_7_foot_protection" file="right_foot_1_7_foot_protection.STL" />
        <mesh name="right_foot_bone_back" file="right_foot_bone_back.STL" />
        <mesh name="right_foot_bone_front" file="right_foot_bone_front.STL" />
        <mesh name="joint_block04" file="joint_block04.STL" />
        <mesh name="dubel04" file="dubel04.STL" />
        <mesh name="tibia_11" file="tibia_11.STL" />
        <mesh name="right_shine_panel" file="right_shine_panel.STL" />
        <mesh name="tibia_12" file="tibia_12.STL" />
        <mesh name="right_knee_bone_1" file="right_knee_bone_1.STL" />
        <mesh name="right_hip_panel" file="right_hip_panel.STL" />
        <mesh name="right_knee_bone_2" file="right_knee_bone_2.STL" />
        <mesh name="joint_block02" file="joint_block02.STL" />
        <mesh name="dubel02" file="dubel02.STL" />
        <mesh name="u_shoulder_1" file="u_shoulder_1.STL" />
        <mesh name="left_humerus_1" file="left_humerus_1.STL" />
        <mesh name="left_radius_1" file="left_radius_1.STL" />
        <mesh name="left_radius_1_1_radius_plate" file="left_radius_1_1_radius_plate.STL" />
        <mesh name="left_boxing_glove" file="left_boxing_glove.STL" />
        <mesh name="left_radius_bone1" file="left_radius_bone1.STL" />
        <mesh name="left_radius_bone2" file="left_radius_bone2.STL" />
        <mesh name="left_humerus_panel" file="left_humerus_panel.STL" />
        <mesh name="u_shoulder_1_bone_front" file="u_shoulder_1_bone_front.STL" />
        <mesh name="u_shoulder_1_bone_back" file="u_shoulder_1_bone_back.STL" />
        <mesh name="u_shoulder_2" file="u_shoulder_2.STL" />
        <mesh name="right_humerus_1" file="right_humerus_1.STL" />
        <mesh name="right_radius_1" file="right_radius_1.STL" />
        <mesh name="right_radius_1_0_radius_plate" file="right_radius_1_0_radius_plate.STL" />
        <mesh name="right_boxing_glove" file="right_boxing_glove.STL" />
        <mesh name="right_radius_bone1" file="right_radius_bone1.STL" />
        <mesh name="right_radius_bone2" file="right_radius_bone2.STL" />
        <mesh name="right_humerus_panel" file="right_humerus_panel.STL" />
        <mesh name="u_shoulder_2_bone_front" file="u_shoulder_2_bone_front.STL" />
        <mesh name="u_shoulder_2_bone_back" file="u_shoulder_2_bone_back.STL" />
        <mesh name="Front_dempher" file="Front_dempher.STL" />
        <mesh name="Handle" file="Handle.STL" />
        <mesh name="DXL_Board" file="DXL_Board.STL" />
        <mesh name="cover_battery" file="cover_battery.STL" />
        <mesh name="front_panel" file="front_panel.STL" />
        <mesh name="left_panel" file="left_panel.STL" />
        <mesh name="right_panel" file="right_panel.STL" />
        <mesh name="num_01" file="num_01.STL" />
        <mesh name="number_01" file="number_01.STL" />
    </asset>

    <asset>
        <texture type="skybox" builtin="gradient" rgb1="0.3 0.5 0.7" rgb2="0 0 0" width="512" height="512"/>

        <texture name="texplane" type="2d" builtin="checker" rgb1=".2 .3 .4" rgb2=".1 0.15 0.2" width="512" height="512" mark="cross" markrgb=".8 .8 .8"/>

        <texture name="texgeom" type="cube" builtin="flat" mark="cross" width="127" height="1278"
            rgb1="0.8 0.6 0.4" rgb2="0.8 0.6 0.4" markrgb="1 1 1" random="0.01"/>

        <material name="matplane" reflectance="0.3" texture="texplane" texrepeat="1 1" texuniform="true"/>

        <material name="matgeom" texture="texgeom" texuniform="true" rgba="0.8 0.6 .4 1"/>
    </asset>

    <worldbody>
        <geom name="floor" pos="0 0 0" size="0 0 .25" type="plane" material="matplane" condim="3"/>

        <light directional="false" diffuse=".2 .2 .2" specular="0 0 0" pos="0 0 5" dir="0 0 -1" castshadow="false"/>
        <light mode="targetbodycom" target="trunk_1" directional="false" diffuse=".8 .8 .8" specular="0.3 0.3 0.3" pos="0 0 4.0" dir="0 0 -1"/>
        <camera name="back" pos="-1 0 1" xyaxes="0 -1 0 1 0 2" mode="trackcom"/>
        <camera name="side" pos="0 -1 1" xyaxes="1 0 0 0 1 2" mode="trackcom"/>
        <body name="base" pos="0 0 0.4">
            <body name="trunk_1" pos="0 0 0" quat="0.707 0 0 0.707">
                <freejoint name="root"/>
                <geom type="mesh" rgba="0.2 0.2 0.2 1" mesh="trunk_1" />
                <geom pos="0.0506584 -0.0242583 0.141" quat="7.81699e-07 0 0 1" type="mesh" rgba="0.79216 0.81961 0.93333 1" mesh="Front_dempher" />
                <geom pos="0.119659 0.0956219 0.215878" quat="0.706998 0.0123898 -0.706998 -0.0123898" type="mesh" rgba="0.698039 0.698039 0.698039 1" mesh="Handle" />
                <body name="dxl_board" pos="0.0506584 0.0131858 0.123" quat="0.5 -0.5 -0.5 0.5">
                    <geom type="mesh" rgba="0.79216 0.81961 0.93333 1" mesh="DXL_Board" />
                    <site name="dxl_board_accelerometer" pos="0 0 0" size=".01 .01 .01" type="box" />
                    <site name="dxl_board_gyro" pos="0 0 0" size=".01 .01 .01" type="box" />
                    
                </body>
                <geom pos="-0.0143415 0.0637418 0" quat="5.52744e-07 5.52744e-07 0.707107 0.707107" type="mesh" rgba="1 0 0 1" mesh="cover_battery" />
                <geom pos="0.0506584 -0.0332583 0.0435" quat="7.81699e-07 0 0 1" type="mesh" rgba="1 0 0 1" mesh="front_panel" />
                <geom pos="0.114644 0.0177528 0.043" quat="0.0110329 0 0 0.999939" type="mesh" rgba="1 0 0 1" mesh="left_panel" />
                <geom pos="-0.0133262 0.0177312 0.043" quat="0.999943 0 0 0.0107024" type="mesh" rgba="1 0 0 1" mesh="right_panel" />
                <geom pos="0.0505128 -0.0332711 0.0497542" quat="0.706434 0.706434 0.030843 0.030843" type="mesh" rgba="0.2 0.2 0.2 1" mesh="num_01" />
                <geom pos="0.0393193 0.0941906 0.0028542" quat="0.098054 0.098054 -0.700275 -0.700275" type="mesh" rgba="0.2 0.2 0.2 1" mesh="number_01" />
                <body name="u_neck_1" pos="0.0506584 -0.0113378 0.184196">
                    <inertial pos="-1.33133e-10 -4.74719e-09 0.0119379" quat="0.5 0.5 0.5 0.5" mass="0.0278443" diaginertia="1.38353e-05 1.36173e-05 5.7683e-06" />
                    
                    <!-- <joint name="head_yaw" type="hinge" pos="0 0 0" axis="0 0 -1"  damping="1.23" frictionloss="5" armature="0.05"/> -->
                    <!-- <joint name="head_yaw_backlash" group="100" type="hinge" pos="0 0 0" axis="0 0 -1" limited="true" range="-0.005 0.005"/> -->
                    
                    <geom type="mesh" rgba="0.2 0.2 0.2 1" mesh="u_neck_1" />
                    <geom pos="-0.0265 0.000100041 0.0352043" quat="0.5 0.5 0.5 -0.5" type="mesh" rgba="0.2 0.2 0.2 1" mesh="u_neck_bone_right" />
                    <geom pos="0.0235 9.99633e-05 0.0352043" quat="0.5 0.5 0.5 -0.5" type="mesh" rgba="0.2 0.2 0.2 1" mesh="u_neck_bone_left" />
                    <body name="head_1" pos="0 7.94737e-05 0.0357043" quat="0.5 -0.5 0.5 -0.5">
                        <inertial pos="0.00291592 -0.0507699 -5.97662e-05" quat="0.706849 0.706842 0.0187562 0.019667" mass="0.45205" diaginertia="0.000508663 0.000438253 0.000251688" />
                        
                        <!-- <joint name="head_pitch" type="hinge" pos="0 0 0" axis="0 0 1" damping="1.23" frictionloss="5" armature="0.05"/> -->
                        <!-- <joint name="head_pitch_backlash" group="100" type="hinge" pos="0 0 0" axis="0 0 1" limited="true" range="-0.005 0.005"/> -->

                        <geom type="mesh" rgba="0.2 0.2 0.2 1" mesh="head_1" />
                        <geom pos="-0.0133327 -0.0476 -0.017" quat="0 0.707107 0 0.707106" type="mesh" rgba="0.2 0.2 0.2 1" mesh="Head_Up" />
                    </body>
                </body>
                <body name="u_block_2" pos="0.0970334 0.0146146 -0.0089" quat="0 0.706488 -0.707725 0">
                    <inertial pos="0.00599173 -1.00908e-05 0.0136137" quat="0.000505477 0.678064 -0.000806897 0.735002" mass="0.0269256" diaginertia="1.67297e-05 1.61336e-05 6.9952e-06" />
                    
                    <joint name="left_hip_yaw" type="hinge" pos="0 0 0" axis="0 0 -1"  damping="0.5" stiffness="20" frictionloss="5"  limited="true" range = "-0.5 1.5"/>
                    <!-- <joint name="left_hip_yaw_backlash" group="100" type="hinge" pos="0 0 0" axis="0 0 -1" limited="true" range="-0.005 0.005"/> -->
                    
                    <geom type="mesh" rgba="0.2 0.2 0.2 1" mesh="u_block_2" />
                    <geom pos="0.0329179 -5.7535e-05 0.037" quat="0.5 0.5 0.5 -0.5" type="mesh" rgba="0.2 0.2 0.2 1" mesh="u_block_2_bone1" />
                    <geom pos="-0.023385 4.08729e-05 0.037" quat="0.5 0.5 0.5 -0.5" type="mesh" rgba="0.2 0.2 0.2 1" mesh="u_block_2_bone2" />
                    <body name="mx106_block_2" pos="0 0 0.04" quat="0.5 -0.5 -0.5 0.5">
                        <inertial pos="5.15734e-05 -0.0158297 0.0220983" quat="1 0 0 0" mass="0.356029" diaginertia="0.000366976 0.000311782 0.000150052" />
                        
                        <joint name="left_hip_roll" type="hinge" pos="0 0 0" axis="0 0 -1" damping="0.5" stiffness="20" frictionloss="5"  limited="true" range="-0.7 1.0"/>
                        <!-- <joint name="left_hip_roll_backlash" group="100" type="hinge" pos="0 0 0" axis="0 0 -1" limited="true" range="-0.005 0.005"/> -->
                        
                        <geom type="mesh" rgba="0.2 0.2 0.2 1" mesh="mx106_block_2" />
                        <geom pos="0 0 0.014722" quat="0.5 -0.5 0.5 -0.5" type="mesh" rgba="0.2 0.2 0.2 1" mesh="joint_block01" />
                        <geom pos="-1.36016e-08 0 0.023422" quat="1 -9.16352e-09 -7.81699e-07 7.45057e-09" type="mesh" rgba="0.2 0.2 0.2 1" mesh="dubel01" />
                        <body name="left_knee_1" pos="0 0 0" quat="0.707107 0 0.707107 0">
                            <inertial pos="-2.19976e-05 -0.108796 -0.000922573" quat="0.725498 0.688224 0 0" mass="0.229478" diaginertia="0.000327608 0.000293228 8.86064e-05" />
                            
                            <joint name="left_hip_pitch" type="hinge" pos="0 0 0" axis="0 0 -1" damping="0.5" stiffness="20" frictionloss="5"  limited="true" range="-2.1 1.0"/>
                            <!-- <joint name="left_hip_pitch_backlash" group="100" type="hinge" pos="0 0 0" axis="0 0 -1" limited="true" range="-0.005 0.005"/> -->
                            
                            <geom type="mesh" rgba="0.2 0.2 0.2 1" mesh="left_knee_1" />
                            <geom pos="-2.19531e-05 -0.055 -0.03" quat="0 0 1 0" type="mesh" rgba="0.2 0.2 0.2 1" mesh="left_knee_bone_1" />
                            <geom pos="-2.19531e-05 -0.055 -0.03" quat="0 0 1 0" type="mesh" rgba="1 0 0 1" mesh="left_hip_panel" />
                            <geom pos="-2.20407e-05 -0.128 0.026" quat="0.5 -0.5 -0.5 0.5" type="mesh" rgba="0.2 0.2 0.2 1" mesh="left_knee_bone_2" />
                            <body name="tibia_2" pos="-2.19547e-05 -0.141 -0.029" quat="0 1 0 0">
                                <inertial pos="0.00453397 0.0676196 -0.026272" quat="0.686939 0.726604 0.00837443 0.00951759" mass="0.0696482" diaginertia="0.000177805 0.000141467 5.69954e-05" />
                                
                                <joint name="left_knee" type="hinge" pos="0 0 0" axis="0 0 1" damping="0.5" stiffness="20" frictionloss="5"  limited="true" range="0.0 1.7"/>
                                <!-- <joint name="left_knee_backlash" group="100" type="hinge" pos="0 0 0" axis="0 0 1" limited="true" range="-0.005 0.005"/> -->

                                <geom type="mesh" rgba="0.2 0.2 0.2 1" mesh="tibia_2" />
                                <geom pos="-0.00141422 0.0350503 -0.003" quat="0 1 0 0" type="mesh" rgba="0.2 0.2 0.2 1" mesh="tibia_21" />
                                <geom pos="0.00350175 0.0920354 0.001" quat="-0.0494213 0 0 0.998778" type="mesh" rgba="1 0 0 1" mesh="left_shin_panel" />
                                <geom pos="0.0219202 0.0583848 -0.055" quat="0 0 0 1" type="mesh" rgba="0.2 0.2 0.2 1" mesh="tibia_22" />
                                <body name="mx106_block_mir_2" pos="0 0.14 0" quat="0 1 0 0">
                                    <inertial pos="-0.0220763 0.0158297 0.0290516" quat="0.00915433 0.705801 -0.0327047 0.707595" mass="0.356029" diaginertia="0.000366976 0.000311782 0.000150052" />
                                    
                                    <joint name="left_ankle_pitch" type="hinge" pos="0 0 0" axis="0 0 -1" damping="0.5" stiffness="20" frictionloss="5"  limited="true" range="-0.8 1.0"/>
                                    <!-- <joint name="left_ankle_pitch_backlash" group="100" type="hinge" pos="0 0 0" axis="0 0 -1" limited="true" range="-0.005 0.005"/> -->
                                    
                                    <geom type="mesh" rgba="0.2 0.2 0.2 1" mesh="mx106_block_mir_2" />
                                    <geom pos="0 0 0.00949997" quat="0.707107 0 0 0.707107" type="mesh" rgba="0.2 0.2 0.2 1" mesh="joint_block03" />
                                    <geom pos="0 0 0.00889992" quat="0 0.707107 0 0.707107" type="mesh" rgba="0.2 0.2 0.2 1" mesh="dubel03" />
                                    <body name="left_foot_1" pos="0.00827101 0 0.029" quat="7.45058e-09 0.707107 7.45058e-09 -0.707107">
                                        <inertial pos="0.00414743 0.0304994 -0.0352501" quat="0.695396 -0.0257124 0.026305 0.71768" mass="0.473901" diaginertia="0.00130021 0.00119674 0.000218674" />
                                        
                                        <!-- <joint name="left_ankle_roll" type="hinge" pos="0 0 0" axis="0 0 -1" damping="1.23" frictionloss="5" armature="0.05"/> -->
                                        <!-- <joint name="left_ankle_roll_backlash" group="100" type="hinge" pos="0 0 0" axis="0 0 -1" limited="true" range="-0.005 0.005"/> -->
                                        
                                        <geom type="mesh" rgba="0.2 0.2 0.2 1" mesh="left_foot_1" />
                                        <geom pos="0.0055 0.04 -0.0858033" quat="0.690665 0.723162 0.00340654 0.00263633" type="mesh" rgba="0.2 0.2 0.2 1" mesh="left_foot_1_0_foot_protection" />
                                        
                                        <geom pos="-0.0325 0.06 -0.0778033" quat="0 0 0 1" type="mesh" rgba="0.2 0.2 0.2 1" mesh="left_foot_cleat_front_right" />
                                        <site name="left_foot_cleat_front_right" pos="-0.0325 0.07 -0.0778033" quat="0 0 0 1" />

                                        <geom pos="0.0435 0.06 -0.0778033" quat="0 0 0 1" type="mesh" rgba="0.2 0.2 0.2 1" mesh="left_foot_cleat_front_left" />
                                        <site name="left_foot_cleat_front_left" pos="0.0435 0.06 -0.0778033" quat="0 0 0 1" />

                                        <geom pos="-0.0325 0.06 0.0638054" quat="0 1 0 0" type="mesh" rgba="0.2 0.2 0.2 1" mesh="left_foot_cleat_back_right" />
                                        <site name="left_foot_cleat_back_right" pos="-0.0325 0.06 0.0638054" quat="0 1 0 0" />

                                        <geom pos="0.0435 0.06 0.0638054" quat="0 1 0 0" type="mesh" rgba="0.2 0.2 0.2 1" mesh="left_foot_cleat_back_left" />
                                        <site name="left_foot_cleat_back_left" pos="0.0435 0.06 0.0638054" quat="0 1 0 0" />
                                        
                                        <geom pos="0 0 0.0328961" quat="0.5 -0.5 -0.5 0.5" type="mesh" rgba="0.2 0.2 0.2 1" mesh="left_foot_bone_back" />
                                        <geom pos="0 0 -0.0234439" quat="0.499999 -0.500001 -0.500001 0.499999" type="mesh" rgba="0.752941 0 0.752941 1" mesh="left_foot_bone_front" />
                                    </body>
                                </body>
                            </body>
                        </body>
                    </body>
                </body>
                <body name="u_block_1" pos="0.00428344 0.0146147 -0.0089" quat="0 0.707107 -0.707107 0">
                    <inertial pos="0.00599174 2.69365e-09 0.0136137" quat="0 0.678064 0 0.735003" mass="0.0269256" diaginertia="1.67297e-05 1.61336e-05 6.99521e-06" />
                    
                    <joint name="right_hip_yaw" type="hinge" pos="0 0 0" axis="0 0 -1" damping="0.5" stiffness="20" frictionloss="5" limited="true" range = "-0.5 1.5"/>
                    <!-- <joint name="right_hip_yaw_backlash" group="100" type="hinge" pos="0 0 0" axis="0 0 -1" limited="true" range="-0.005 0.005"/> -->

                    <geom type="mesh" rgba="0.2 0.2 0.2 1" mesh="u_block_1" />
                    <geom pos="0.032918 0 0.037" quat="0.5 0.5 0.5 -0.5" type="mesh" rgba="0.2 0.2 0.2 1" mesh="u_block_1_bone1" />
                    <geom pos="-0.023385 0 0.037" quat="0.5 0.5 0.5 -0.5" type="mesh" rgba="0.2 0.2 0.2 1" mesh="u_block_1_bone2" />
                    <body name="mx106_block_mir_1" pos="0 0 0.04" quat="0.5 -0.5 0.5 -0.5">
                        <inertial pos="5.15746e-05 -0.0158297 -0.0220983" quat="0.999422 -0.0295988 0.00126868 0.0166526" mass="0.356029" diaginertia="0.000366976 0.000311782 0.000150052" />
                        
                        <joint name="right_hip_roll" type="hinge" pos="0 0 0" axis="0 0 1" damping="0.5" stiffness="20" frictionloss="5"  limited ='true' range="-0.7 1.0"/>
                        <!-- <joint name="right_hip_roll_backlash" group="100" type="hinge" pos="0 0 0" axis="0 0 1" limited="true" range="-0.005 0.005"/> -->
                        
                        <geom type="mesh" rgba="0.2 0.2 0.2 1" mesh="mx106_block_mir_1" />
                        <geom pos="-0.017 -0.0145 -0.016722" quat="0.5 0.5 -0.5 -0.5" type="mesh" rgba="0.2 0.2 0.2 1" mesh="joint_block02" />
                        <geom pos="-0.015 -0.015 -0.032422" type="mesh" rgba="0.2 0.2 0.2 1" mesh="dubel02" />
                        <body name="right_knee_1" pos="-0.029 0 -2.2e-05" quat="0.707107 0 0.707107 0">
                            <inertial pos="6.56694e-10 -0.108796 0.0280774" quat="0.725498 0.688224 0 0" mass="0.229478" diaginertia="0.000327608 0.000293228 8.86064e-05" />
                            
                            <joint name="right_hip_pitch" type="hinge" pos="0 0 0" axis="0 0 1" damping="0.5" stiffness="20" frictionloss="5"  limited="true" range="-2.1 1.0"/>
                            <!-- <joint name="right_hip_pitch_backlash" group="100" type="hinge" pos="0 0 0" axis="0 0 1" limited="true" range="-0.005 0.005"/> -->
                            
                            <geom type="mesh" rgba="0.2 0.2 0.2 1" mesh="right_knee_1" />
                            <geom pos="-2.2e-05 -0.128 0.003" quat="0.5 0.5 0.5 0.5" type="mesh" rgba="0.2 0.2 0.2 1" mesh="right_knee_bone_1" />
                            <geom pos="0 -0.055 -0.001" quat="-7.81699e-07 0 1 0" type="mesh" rgba="1 0 0 1" mesh="right_hip_panel" />
                   f         <geom pos="-2.2e-05 -0.128 0.058" quat="0.5 0.5 0.5 0.5" type="mesh" rgba="0.2 0.2 0.2 1" mesh="right_knee_bone_2" />
                            <body name="tibia_1" pos="0 -0.141 0.055" quat="0 0 0 1">
                                <inertial pos="0.00453401 0.0676196 -0.028728" quat="0.726604 0.686939 0.00951817 0.00837388" mass="0.0696482" diaginertia="0.000177805 0.000141467 5.69954e-05" />
                                
                                <joint name="right_knee" type="hinge" pos="0 0 0" axis="0 0 1" damping="0.5" stiffness="20" frictionloss="5"  limited="true" range="0.0 1.7"/>
                                <!-- <joint name="right_knee_backlash" group="100" type="hinge" pos="0 0 0" axis="0 0 1" limited="true" range="-0.005 0.005"/> -->
                                
                                <geom type="mesh" rgba="0.2 0.2 0.2 1" mesh="tibia_1" />
                                <geom pos="-0.00169887 0.0350365 -0.052" quat="0.707106 0 -0.707107 0" type="mesh" rgba="0.2 0.2 0.2 1" mesh="tibia_11" />
                                <geom pos="0.00350176 0.0920354 -0.056" quat="-3.8633e-08 -0.998778 -0.0494213 -7.80752e-07" type="mesh" rgba="1 0 0 1" mesh="right_shine_panel" />
                                <geom pos="0.0219203 0.0583848 0" quat="0.497808 -0.497808 -0.502183 0.502183" type="mesh" rgba="0.2 0.2 0.2 1" mesh="tibia_12" />
                                <body name="mx106_block_1" pos="0 0.14 -0.026" quat="0 0 0 -1">
                                    <inertial pos="0.0220763 0.0158297 5.15964e-05" quat="-0.0327051 0.707596 0.00915386 0.705801" mass="0.356029" diaginertia="0.000366976 0.000311782 0.000150052" />
                                    
                                    <joint name="right_ankle_pitch" type="hinge" pos="0 0 0" axis="0 0 1" damping="0.5" stiffness="20" frictionloss="5" limited="true" range="-0.8 1.0"/>
                                    <!-- <joint name="right_ankle_pitch_backlash" group="100" type="hinge" pos="0 0 0" axis="0 0 1" limited="true" range="-0.005 0.005"/> -->
                                    
                                    <geom type="mesh" rgba="0.2 0.2 0.2 1" mesh="mx106_block_1" />
                                    <geom pos="0 0 -0.0195" quat="0.707107 0 0 0.707107" type="mesh" rgba="0.2 0.2 0.2 1" mesh="joint_block04" />
                                    <geom pos="0.0344 0.045 0" quat="0.707107 4.80107e-09 0.707107 -4.80107e-09" type="mesh" rgba="0.2 0.2 0.2 1" mesh="dubel04" />
                                    <body name="right_foot_1" pos="-0.00630123 0 0" quat="0.707107 7.41763e-08 0.707107 -6.66368e-08">
                                        <inertial pos="0.0062165 -0.0304994 -0.0372199" quat="0.708542 0.0138007 -0.0382562 0.704496" mass="0.473901" diaginertia="0.00130073 0.00119802 0.000218113" />
                                        
                                        <!-- <joint name="right_ankle_roll" pos="0 0 0" axis="0 0 -1" range="-3.14 3.14"   damping="1.23" frictionloss="5" armature="0.05"/> -->
                                        <!-- <joint name="right_ankle_roll_backlash" group="100" type="hinge" pos="0 0 0" axis="0 0 -1" limited="true" range="-0.005 0.005"/> -->
                                        
                                        
                                        <geom type="mesh" rgba="0.2 0.2 0.2 1" mesh="right_foot_1" />

                                        <geom pos="-0.0325 -0.06 -0.0797731" type="mesh" rgba="0.2 0.2 0.2 1" mesh="right_foot_cleat_front_left" />
                                        <site name="right_foot_cleat_front_left" pos="-0.0325 -0.06 -0.0797731" />
                                        
                                        <geom pos="-0.0325 -0.06 0.0618356" quat="0 0 1 0" type="mesh" rgba="0.2 0.2 0.2 1" mesh="right_foot_cleat_back_left" />
                                        <site name="right_foot_cleat_back_left" pos="-0.0325 -0.06 0.0618356" quat="0 0 1 0" />
                                        
                                        <geom pos="0.0435 -0.06 0.0618356" quat="0 0 1 0" type="mesh" rgba="0.2 0.2 0.2 1" mesh="right_foot_cleat_back_right" />
                                        <site name="right_foot_cleat_back_right" pos="0.0435 -0.06 0.0618356" quat="0 0 1 0" />
                                        
                                        <geom pos="0.0435 -0.06 -0.0797731" type="mesh" rgba="0.2 0.2 0.2 1" mesh="right_foot_cleat_front_right" />
                                        <site name="right_foot_cleat_front_right" pos="0.0435 -0.06 -0.0797731" />
                                        
                                        <geom pos="0.0055 -0.04 -0.0877731" quat="0 0 0.707107 0.707107" type="mesh" rgba="0.2 0.2 0.2 1" mesh="right_foot_1_7_foot_protection" />
                                        <geom pos="0.00949975 0 0.0075043" quat="0.5 -0.5 0.5 -0.5" type="mesh" rgba="0.2 0.2 0.2 1" mesh="right_foot_bone_back" />
                                        <geom pos="0 0 -0.0254357" quat="0.499999 -0.500001 0.500001 -0.499999" type="mesh" rgba="0.752941 0 0.752941 1" mesh="right_foot_bone_front" />
                                    </body>
                                </body>
                            </body>
                        </body>
                    </body>
                </body>
                <body name="u_shoulder_1" pos="0.123658 -0.00625845 0.155" quat="0.5 -0.5 0.5 -0.5">
                    <inertial pos="1.24137e-08 0.00176186 0.00794026" quat="-0.189311 0.681294 -0.189311 0.681293" mass="0.0640106" diaginertia="3.03725e-05 2.32131e-05 1.81561e-05" />
                    
                    <!-- <joint name="left_shoulder_pitch" type="hinge" pos="0 0 0" axis="0 0 1" damping="1.23" frictionloss="5" armature="0.05"/> -->
                    <!-- <joint name="left_shoulder_pitch_backlash" group="100" type="hinge" pos="0 0 0" axis="0 0 1" limited="true" range="-0.005 0.005"/> -->
                    
                    <geom type="mesh" rgba="0.2 0.2 0.2 1" mesh="u_shoulder_1" />
                    <geom pos="0.0235 0 0.000500095" quat="0.5 0.5 -0.5 -0.5" type="mesh" rgba="0.2 0.2 0.2 1" mesh="u_shoulder_1_bone_front" />
                    <geom pos="-0.0265 0 0.000500173" quat="0.5 0.5 -0.5 -0.5" type="mesh" rgba="0.2 0.2 0.2 1" mesh="u_shoulder_1_bone_back" />
                    <body name="left_humerus_1" pos="0.0103499 0.03 0.0355001" quat="0 -0.707106 0 0.707107">
                        <inertial pos="-0.000429571 -0.0568917 0.0102473" quat="0.502436 0.492044 -0.488579 0.51647" mass="0.323776" diaginertia="0.000127873 0.000125577 8.32034e-05" />
                        
                        <!-- <joint name="left_shoulder_roll" type="hinge" pos="0 0 0" axis="0 0 -1" damping="1.23" frictionloss="5" armature="0.05"/> -->
                        <!-- <joint name="left_shoulder_roll_backlash" group="100" type="hinge" pos="0 0 0" axis="0 0 -1" limited="true" range="-0.005 0.005"/> -->
                        
                        
                        <geom type="mesh" rgba="0.2 0.2 0.2 1" mesh="left_humerus_1" />
                        <geom pos="-0.021 -0.0425 0.00994983" quat="0.707107 0 0.707107 0" type="mesh" rgba="1 0 0 1" mesh="left_humerus_panel" />
                        <body name="left_radius_1" pos="-0.0255 -0.1145 0.00994983" quat="0 0.707107 0 0.707106">
                            <inertial pos="0.0276835 0.0905651 0.0255" quat="0.495657 0.504305 -0.495657 0.504305" mass="0.0838657" diaginertia="0.00039104 0.000384205 3.00183e-05" />
                            
                            <!-- <joint name="left_elbow" type="hinge" pos="0 0 0" axis="0 0 -1" damping="1.23" frictionloss="5" armature="0.05"/> -->
                            <!-- <joint name="left_elbow_backlash" group="100" type="hinge" pos="0 0 0" axis="0 0 -1" limited="true" range="-0.005 0.005"/> -->
                            
                            <geom type="mesh" rgba="0.2 0.2 0.2 1" mesh="left_radius_1" />
                            <geom pos="0.0260001 0.1589 0.0395" quat="0 0 0 1" type="mesh" rgba="0.2 0.2 0.2 1" mesh="left_radius_1_1_radius_plate" />
                            <body name="left_boxing_glove">
                            <geom pos="0.0260001 0.1589 0.0255" quat="0 0 0 1" type="mesh" rgba="0.2 0.2 0.2 1" mesh="left_boxing_glove" />
                            </body>
                            <geom pos="0.036 0 0.00199994" quat="0.5 0.5 0.5 -0.5" type="mesh" rgba="0.2 0.2 0.2 1" mesh="left_radius_bone1" />
                            <geom pos="0.0360001 0 0.0489999" quat="0.5 0.5 0.5 -0.5" type="mesh" rgba="0.2 0.2 0.2 1" mesh="left_radius_bone2" />
                        </body>
                    </body>
                </body>
                <body name="u_shoulder_2" pos="-0.0223415 -0.00625822 0.155" quat="0.5 0.5 0.5 0.5">
                    <inertial pos="0 -0.00176186 -0.00794026" quat="-0.189311 0.681294 -0.189311 0.681294" mass="0.0640106" diaginertia="3.03725e-05 2.32131e-05 1.81561e-05" />
                    
                    <!-- <joint name="right_shoulder_pitch" type="hinge" pos="0 0 0" axis="0 0 1" damping="1.23" frictionloss="5" armature="0.05"/> -->
                    <!-- <joint name="right_shoulder_pitch_backlash" group="100" type="hinge" pos="0 0 0" axis="0 0 1" limited="true" range="-0.005 0.005"/> -->

                    <geom type="mesh" rgba="0.2 0.2 0.2 1" mesh="u_shoulder_2" />
                    <geom pos="-0.0265 0 -0.000500134" quat="0.5 -0.5 -0.5 0.5" type="mesh" rgba="0.2 0.2 0.2 1" mesh="u_shoulder_2_bone_front" />
                    <geom pos="0.0235 0 -0.000500134" quat="0.5 -0.5 -0.5 0.5" type="mesh" rgba="0.2 0.2 0.2 1" mesh="u_shoulder_2_bone_back" />
                    <body name="right_humerus_1" pos="0.00911335 -0.03 -0.0355001" quat="0.707107 0 -0.707106 0">
                        <inertial pos="-0.000429583 -0.0568917 0.00899464" quat="0.485314 0.512881 -0.505864 0.495505" mass="0.323776" diaginertia="0.000127871 0.000125577 8.32044e-05" />
                        
                        <!-- <joint name="right_shoulder_roll" type="hinge" pos="0 0 0" axis="0 0 1" damping="1.23" frictionloss="5" armature="0.05"/> -->
                        <!-- <joint name="right_shoulder_roll_backlash" group="100" type="hinge" pos="0 0 0" axis="0 0 1" limited="true" range="-0.005 0.005"/> -->

                        <geom type="mesh" rgba="0.2 0.2 0.2 1" mesh="right_humerus_1" />
                        <geom pos="-0.021 -0.0425 0.00911332" quat="0.707107 0 0.707107 0" type="mesh" rgba="1 0 0 1" mesh="right_humerus_panel" />
                        <body name="right_radius_1" pos="-0.0140206 -0.1145 0.00911333" quat="1.56919e-10 -0.707107 1.56919e-10 0.707106">
                            <inertial pos="0.0276834 0.0906275 -0.0140206" quat="0.495656 0.504306 -0.495656 0.504306" mass="0.0838657" diaginertia="0.000391496 0.000384661 3.00182e-05" />
                            
                            <!-- <joint name="right_elbow" type="hinge" pos="0 0 0" axis="0 0 -1" damping="1.23" frictionloss="5" armature="0.05"/> -->
                            <!-- <joint name="right_elbow_backlash" group="100" type="hinge" pos="0 0 0" axis="0 0 -1" limited="true" range="-0.005 0.005"/> -->

                            <geom type="mesh" rgba="0.2 0.2 0.2 1" mesh="right_radius_1" />
                            <geom pos="0.026 0.159 -0.0280206" quat="0.707107 0 0 -0.707107" type="mesh" rgba="0.2 0.2 0.2 1" mesh="right_radius_1_0_radius_plate" />
                            <body name="right_boxing_glove">
                            <geom pos="0.026 0.159 -0.0140206" quat="0 0 0 -1" type="mesh" rgba="0.2 0.2 0.2 1" mesh="right_boxing_glove" />
                            </body>
                            <geom pos="0.036 0 0.00947939" quat="0.5 0.5 0.5 -0.5" type="mesh" rgba="0.2 0.2 0.2 1" mesh="right_radius_bone1" />
                            <geom pos="0.036 0 -0.0375206" quat="0.5 0.5 0.5 -0.5" type="mesh" rgba="0.2 0.2 0.2 1" mesh="right_radius_bone2" />
                        </body>
                    </body>
                </body>
            </body>
        </body>
    </worldbody>

    <!-- <actuator>
        <position name="head_yaw" kp="32" joint="head_yaw" forcelimited="true" forcerange="-10.00 10.00"/>
        <position name="head_pitch" kp="32" joint="head_pitch" forcelimited="true" forcerange="-10.00 10.00"/>
        <position name="right_shoulder_pitch" kp="32" joint="right_shoulder_pitch" forcelimited="true" forcerange="-10.00 10.00"/>
        <position name="right_shoulder_roll" kp="32" joint="right_shoulder_roll" forcelimited="true" forcerange="-10.00 10.00"/>
        <position name="left_shoulder_pitch" kp="32" joint="left_shoulder_pitch" forcelimited="true" forcerange="-10.00 10.00"/>
        <position name="left_shoulder_roll" kp="32" joint="left_shoulder_roll" forcelimited="true" forcerange="-10.00 10.00"/>
        <position name="right_elbow" kp="32" joint="right_elbow" forcelimited="true" forcerange="-10.00 10.00"/>
        <position name="left_elbow" kp="32" joint="left_elbow" forcelimited="true" forcerange="-10.00 10.00"/>
        <position name="right_hip_pitch" kp="32" joint="right_hip_pitch" forcelimited="true" forcerange="-10.00 10.00"/>
        <position name="right_hip_roll" kp="32" joint="right_hip_roll" forcelimited="true" forcerange="-10.00 10.00"/>
        <position name="right_hip_yaw" kp="32" joint="right_hip_yaw" forcelimited="true" forcerange="-10.00 10.00"/>
        <position name="left_hip_pitch" kp="32" joint="left_hip_pitch" forcelimited="true" forcerange="-10.00 10.00"/>
        <position name="left_hip_roll" kp="32" joint="left_hip_roll" forcelimited="true" forcerange="-10.00 10.00"/>
        <position name="left_hip_yaw" kp="32" joint="left_hip_yaw" forcelimited="true" forcerange="-10.00 10.00"/>
        <position name="right_knee" kp="32" joint="right_knee" forcelimited="true" forcerange="-10.00 10.00"/>
        <position name="left_knee" kp="32" joint="left_knee" forcelimited="true" forcerange="-10.00 10.00"/>
        <position name="left_ankle_pitch" kp="32" joint="left_ankle_pitch" forcelimited="true" forcerange="-10.00 10.00"/>
        <position name="left_ankle_roll" kp="32" joint="left_ankle_roll" forcelimited="true" forcerange="-10.00 10.00"/>
        <position name="right_ankle_pitch" kp="32" joint="right_ankle_pitch" forcelimited="true" forcerange="-10.00 10.00"/>
        <position name="right_ankle_roll" kp="32" joint="right_ankle_roll" forcelimited="true" forcerange="-10.00 10.00"/>
    </actuator> -->

    <sensor>
    <framepos name="trunk_position" objtype="body" objname="trunk_1"/>
    <framequat name="trunk_quaternion" objtype="body" objname="trunk_1"/>
    <gyro name="imu/gyro" site="dxl_board_gyro" />
    <accelerometer name="imu/accelerometer" site="dxl_board_accelerometer" />

    <touch name="left_pressure/pressure_0" site="left_foot_cleat_front_right" />
    <touch name="left_pressure/pressure_1" site="left_foot_cleat_back_right" />
    <touch name="left_pressure/pressure_2" site="left_foot_cleat_back_left" />
    <touch name="left_pressure/pressure_3" site="left_foot_cleat_front_left" />
    
    <touch name="right_pressure/pressure_0" site="right_foot_cleat_front_right" />
    <touch name="right_pressure/pressure_1" site="right_foot_cleat_back_right" />
    <touch name="right_pressure/pressure_2" site="right_foot_cleat_back_left" />
    <touch name="right_pressure/pressure_3" site="right_foot_cleat_front_left" />

    <jointpos name="head_yaw/position" joint="head_yaw" />
    <jointpos name="head_pitch/position" joint="head_pitch" />
    <jointpos name="right_shoulder_pitch/position" joint="right_shoulder_pitch" />
    <jointpos name="right_shoulder_roll/position" joint="right_shoulder_roll" />
    <jointpos name="left_shoulder_pitch/position" joint="left_shoulder_pitch" />
    <jointpos name="left_shoulder_roll/position" joint="left_shoulder_roll" />
    <jointpos name="right_elbow/position" joint="right_elbow" />
    <jointpos name="left_elbow/position" joint="left_elbow" />
    <jointpos name="right_hip_pitch/position" joint="right_hip_pitch" />
    <jointpos name="right_hip_roll/position" joint="right_hip_roll" />
    <jointpos name="right_hip_yaw/position" joint="right_hip_yaw" />
    <jointpos name="left_hip_pitch/position" joint="left_hip_pitch" />
    <jointpos name="left_hip_roll/position" joint="left_hip_roll" />
    <jointpos name="left_hip_yaw/position" joint="left_hip_yaw" />
    <jointpos name="right_knee/position" joint="right_knee" />
    <jointpos name="left_knee/position" joint="left_knee" />
    <jointpos name="left_ankle_pitch/position" joint="left_ankle_pitch" />
    <jointpos name="left_ankle_roll/position" joint="left_ankle_roll" />
    <jointpos name="right_ankle_pitch/position" joint="right_ankle_pitch" />
    <jointpos name="right_ankle_roll/position" joint="right_ankle_roll" />

    <jointvel name="head_yaw/velocity" joint="head_yaw" />
    <jointvel name="head_pitch/velocity" joint="head_pitch" />
    <jointvel name="right_shoulder_pitch/velocity" joint="right_shoulder_pitch" />
    <jointvel name="right_shoulder_roll/velocity" joint="right_shoulder_roll" />
    <jointvel name="left_shoulder_pitch/velocity" joint="left_shoulder_pitch" />
    <jointvel name="left_shoulder_roll/velocity" joint="left_shoulder_roll" />
    <jointvel name="right_elbow/velocity" joint="right_elbow" />
    <jointvel name="left_elbow/velocity" joint="left_elbow" />
    <jointvel name="right_hip_pitch/velocity" joint="right_hip_pitch" />
    <jointvel name="right_hip_roll/velocity" joint="right_hip_roll" />
    <jointvel name="right_hip_yaw/velocity" joint="right_hip_yaw" />
    <jointvel name="left_hip_pitch/velocity" joint="left_hip_pitch" />
    <jointvel name="left_hip_roll/velocity" joint="left_hip_roll" />
    <jointvel name="left_hip_yaw/velocity" joint="left_hip_yaw" />
    <jointvel name="right_knee/velocity" joint="right_knee" />
    <jointvel name="left_knee/velocity" joint="left_knee" />
    <jointvel name="left_ankle_pitch/velocity" joint="left_ankle_pitch" />
    <jointvel name="left_ankle_roll/velocity" joint="left_ankle_roll" />
    <jointvel name="right_ankle_pitch/velocity" joint="right_ankle_pitch" />
    <jointvel name="right_ankle_roll/velocity" joint="right_ankle_roll" />
    
    </sensor>
</mujoco>
